src/main/resources/output.csv
#ActionType,OrderID,Symbol,Price,Side,OrderQuantity,FillPrice,FillQuantity
ACK,Order1,0700.HK,MKT,BUY,20000,null,null
ACK,Order3,0700.HK,610,SELL,10000,null,null
ACK,Order2,0700.HK,MKT,SELL,10000,null,null
FILL,Order1,0700.HK,MKT,BUY,20000,610,10000
FILL,Order2,0700.HK,MKT,SELL,10000,610,10000
FILL,Order1,0700.HK,MKT,BUY,10000,610,10000
FILL,Order3,0700.HK,610,SELL,10000,610,10000
